Traceback (most recent call last):
  File "/home/victor/anaconda3/envs/jupyterbook/lib/python3.13/site-packages/jupyter_core/utils/__init__.py", line 154, in wrapped
    asyncio.get_running_loop()
    ~~~~~~~~~~~~~~~~~~~~~~~~^^
RuntimeError: no running event loop

During handling of the above exception, another exception occurred:

Traceback (most recent call last):
  File "/home/victor/anaconda3/envs/jupyterbook/lib/python3.13/site-packages/jupyter_cache/executors/utils.py", line 58, in single_nb_execution
    executenb(
    ~~~~~~~~~^
        nb,
        ^^^
    ...<4 lines>...
        **kwargs,
        ^^^^^^^^^
    )
    ^
  File "/home/victor/anaconda3/envs/jupyterbook/lib/python3.13/site-packages/nbclient/client.py", line 1319, in execute
    return NotebookClient(nb=nb, resources=resources, km=km, **kwargs).execute()
           ~~~~~~~~~~~~~~~~~~~~~~~~~~~~~~~~~~~~~~~~~~~~~~~~~~~~~~~~~~~~~~~~~~~^^
  File "/home/victor/anaconda3/envs/jupyterbook/lib/python3.13/site-packages/jupyter_core/utils/__init__.py", line 158, in wrapped
    return loop.run_until_complete(inner)
           ~~~~~~~~~~~~~~~~~~~~~~~^^^^^^^
  File "/home/victor/anaconda3/envs/jupyterbook/lib/python3.13/asyncio/base_events.py", line 725, in run_until_complete
    return future.result()
           ~~~~~~~~~~~~~^^
  File "/home/victor/anaconda3/envs/jupyterbook/lib/python3.13/site-packages/nbclient/client.py", line 709, in async_execute
    await self.async_execute_cell(
        cell, index, execution_count=self.code_cells_executed + 1
    )
  File "/home/victor/anaconda3/envs/jupyterbook/lib/python3.13/site-packages/nbclient/client.py", line 1062, in async_execute_cell
    await self._check_raise_for_error(cell, cell_index, exec_reply)
  File "/home/victor/anaconda3/envs/jupyterbook/lib/python3.13/site-packages/nbclient/client.py", line 918, in _check_raise_for_error
    raise CellExecutionError.from_cell_and_msg(cell, exec_reply_content)
nbclient.exceptions.CellExecutionError: An error occurred while executing the following cell:
------------------
from google.colab import drive
drive.mount('/content/drive')
------------------


[31m---------------------------------------------------------------------------[39m
[31mModuleNotFoundError[39m                       Traceback (most recent call last)
[36mCell[39m[36m [39m[32mIn[1][39m[32m, line 1[39m
[32m----> [39m[32m1[39m [38;5;28;01mfrom[39;00m[38;5;250m [39m[34;01mgoogle[39;00m[34;01m.[39;00m[34;01mcolab[39;00m[38;5;250m [39m[38;5;28;01mimport[39;00m drive
[32m      2[39m drive.mount([33m'[39m[33m/content/drive[39m[33m'[39m)

[36mFile [39m[32m~/anaconda3/envs/jupyterbook/lib/python3.13/site-packages/google/colab/__init__.py:20[39m
[32m     17[39m [38;5;28;01mfrom[39;00m[38;5;250m [39m[34;01m__future__[39;00m[38;5;250m [39m[38;5;28;01mimport[39;00m division [38;5;28;01mas[39;00m _
[32m     18[39m [38;5;28;01mfrom[39;00m[38;5;250m [39m[34;01m__future__[39;00m[38;5;250m [39m[38;5;28;01mimport[39;00m print_function [38;5;28;01mas[39;00m _
[32m---> [39m[32m20[39m [38;5;28;01mfrom[39;00m[38;5;250m [39m[34;01mgoogle[39;00m[34;01m.[39;00m[34;01mcolab[39;00m[38;5;250m [39m[38;5;28;01mimport[39;00m _import_hooks
[32m     21[39m [38;5;28;01mfrom[39;00m[38;5;250m [39m[34;01mgoogle[39;00m[34;01m.[39;00m[34;01mcolab[39;00m[38;5;250m [39m[38;5;28;01mimport[39;00m _installation_commands
[32m     22[39m [38;5;28;01mfrom[39;00m[38;5;250m [39m[34;01mgoogle[39;00m[34;01m.[39;00m[34;01mcolab[39;00m[38;5;250m [39m[38;5;28;01mimport[39;00m _shell_customizations

[36mFile [39m[32m~/anaconda3/envs/jupyterbook/lib/python3.13/site-packages/google/colab/_import_hooks/__init__.py:16[39m
[32m      1[39m [38;5;66;03m# Copyright 2018 Google Inc.[39;00m
[32m      2[39m [38;5;66;03m#[39;00m
[32m      3[39m [38;5;66;03m# Licensed under the Apache License, Version 2.0 (the "License");[39;00m
[32m   (...)[39m[32m     12[39m [38;5;66;03m# See the License for the specific language govestylerning permissions and[39;00m
[32m     13[39m [38;5;66;03m# limitations under the License.[39;00m
[32m     14[39m [33;03m"""Colab import customizations to the IPython runtime."""[39;00m
[32m---> [39m[32m16[39m [38;5;28;01mfrom[39;00m[38;5;250m [39m[34;01mgoogle[39;00m[34;01m.[39;00m[34;01mcolab[39;00m[34;01m.[39;00m[34;01m_import_hooks[39;00m[38;5;250m [39m[38;5;28;01mimport[39;00m _altair
[32m     17[39m [38;5;28;01mfrom[39;00m[38;5;250m [39m[34;01mgoogle[39;00m[34;01m.[39;00m[34;01mcolab[39;00m[34;01m.[39;00m[34;01m_import_hooks[39;00m[38;5;250m [39m[38;5;28;01mimport[39;00m _cv2
[32m     20[39m [38;5;28;01mdef[39;00m[38;5;250m [39m[34m_register_hooks[39m():

[36mFile [39m[32m~/anaconda3/envs/jupyterbook/lib/python3.13/site-packages/google/colab/_import_hooks/_altair.py:16[39m
[32m      1[39m [38;5;66;03m# Copyright 2018 Google Inc. All rights reserved.[39;00m
[32m      2[39m [38;5;66;03m#[39;00m
[32m      3[39m [38;5;66;03m# Licensed under the Apache License, Version 2.0 (the "License");[39;00m
[32m   (...)[39m[32m     12[39m [38;5;66;03m# See the License for the specific language governing permissions and[39;00m
[32m     13[39m [38;5;66;03m# limitations under the License.[39;00m
[32m     14[39m [33;03m"""Import hook for ensuring that Altair's Colab renderer is registered."""[39;00m
[32m---> [39m[32m16[39m [38;5;28;01mimport[39;00m[38;5;250m [39m[34;01mimp[39;00m
[32m     17[39m [38;5;28;01mimport[39;00m[38;5;250m [39m[34;01mlogging[39;00m
[32m     18[39m [38;5;28;01mimport[39;00m[38;5;250m [39m[34;01mos[39;00m

[31mModuleNotFoundError[39m: No module named 'imp'

