Traceback (most recent call last):
  File "/home/victor/anaconda3/envs/jupyterbook/lib/python3.13/site-packages/jupyter_core/utils/__init__.py", line 154, in wrapped
    asyncio.get_running_loop()
    ~~~~~~~~~~~~~~~~~~~~~~~~^^
RuntimeError: no running event loop

During handling of the above exception, another exception occurred:

Traceback (most recent call last):
  File "/home/victor/anaconda3/envs/jupyterbook/lib/python3.13/site-packages/jupyter_cache/executors/utils.py", line 58, in single_nb_execution
    executenb(
    ~~~~~~~~~^
        nb,
        ^^^
    ...<4 lines>...
        **kwargs,
        ^^^^^^^^^
    )
    ^
  File "/home/victor/anaconda3/envs/jupyterbook/lib/python3.13/site-packages/nbclient/client.py", line 1319, in execute
    return NotebookClient(nb=nb, resources=resources, km=km, **kwargs).execute()
           ~~~~~~~~~~~~~~~~~~~~~~~~~~~~~~~~~~~~~~~~~~~~~~~~~~~~~~~~~~~~~~~~~~~^^
  File "/home/victor/anaconda3/envs/jupyterbook/lib/python3.13/site-packages/jupyter_core/utils/__init__.py", line 158, in wrapped
    return loop.run_until_complete(inner)
           ~~~~~~~~~~~~~~~~~~~~~~~^^^^^^^
  File "/home/victor/anaconda3/envs/jupyterbook/lib/python3.13/asyncio/base_events.py", line 725, in run_until_complete
    return future.result()
           ~~~~~~~~~~~~~^^
  File "/home/victor/anaconda3/envs/jupyterbook/lib/python3.13/site-packages/nbclient/client.py", line 709, in async_execute
    await self.async_execute_cell(
        cell, index, execution_count=self.code_cells_executed + 1
    )
  File "/home/victor/anaconda3/envs/jupyterbook/lib/python3.13/site-packages/nbclient/client.py", line 1062, in async_execute_cell
    await self._check_raise_for_error(cell, cell_index, exec_reply)
  File "/home/victor/anaconda3/envs/jupyterbook/lib/python3.13/site-packages/nbclient/client.py", line 918, in _check_raise_for_error
    raise CellExecutionError.from_cell_and_msg(cell, exec_reply_content)
nbclient.exceptions.CellExecutionError: An error occurred while executing the following cell:
------------------
import math
import numpy as np

pi_math = math.pi
pi_np = np.pi
print(pi)
print(pi_np)

n_euler_math = math.e
n_euler_np = np.e
print(n_euler_math)
print(n_euler_np)
------------------


[31m---------------------------------------------------------------------------[39m
[31mNameError[39m                                 Traceback (most recent call last)
[36mCell[39m[36m [39m[32mIn[7][39m[32m, line 6[39m
[32m      4[39m pi_math = math.pi
[32m      5[39m pi_np = np.pi
[32m----> [39m[32m6[39m [38;5;28mprint[39m([43mpi[49m)
[32m      7[39m [38;5;28mprint[39m(pi_np)
[32m      9[39m n_euler_math = math.e

[31mNameError[39m: name 'pi' is not defined

