Traceback (most recent call last):
  File "/home/victor/anaconda3/envs/jupyterbook/lib/python3.13/site-packages/jupyter_core/utils/__init__.py", line 154, in wrapped
    asyncio.get_running_loop()
    ~~~~~~~~~~~~~~~~~~~~~~~~^^
RuntimeError: no running event loop

During handling of the above exception, another exception occurred:

Traceback (most recent call last):
  File "/home/victor/anaconda3/envs/jupyterbook/lib/python3.13/site-packages/jupyter_cache/executors/utils.py", line 58, in single_nb_execution
    executenb(
    ~~~~~~~~~^
        nb,
        ^^^
    ...<4 lines>...
        **kwargs,
        ^^^^^^^^^
    )
    ^
  File "/home/victor/anaconda3/envs/jupyterbook/lib/python3.13/site-packages/nbclient/client.py", line 1319, in execute
    return NotebookClient(nb=nb, resources=resources, km=km, **kwargs).execute()
           ~~~~~~~~~~~~~~~~~~~~~~~~~~~~~~~~~~~~~~~~~~~~~~~~~~~~~~~~~~~~~~~~~~~^^
  File "/home/victor/anaconda3/envs/jupyterbook/lib/python3.13/site-packages/jupyter_core/utils/__init__.py", line 158, in wrapped
    return loop.run_until_complete(inner)
           ~~~~~~~~~~~~~~~~~~~~~~~^^^^^^^
  File "/home/victor/anaconda3/envs/jupyterbook/lib/python3.13/asyncio/base_events.py", line 725, in run_until_complete
    return future.result()
           ~~~~~~~~~~~~~^^
  File "/home/victor/anaconda3/envs/jupyterbook/lib/python3.13/site-packages/nbclient/client.py", line 709, in async_execute
    await self.async_execute_cell(
        cell, index, execution_count=self.code_cells_executed + 1
    )
  File "/home/victor/anaconda3/envs/jupyterbook/lib/python3.13/site-packages/nbclient/client.py", line 1062, in async_execute_cell
    await self._check_raise_for_error(cell, cell_index, exec_reply)
  File "/home/victor/anaconda3/envs/jupyterbook/lib/python3.13/site-packages/nbclient/client.py", line 918, in _check_raise_for_error
    raise CellExecutionError.from_cell_and_msg(cell, exec_reply_content)
nbclient.exceptions.CellExecutionError: An error occurred while executing the following cell:
------------------
# suma
suma = num_int + num_float

# exponencial
exponente = 5**2

# division
cociente = 9/5
cociente_entero = 9//5
residuo = 9%5

print("suma =",suma)
print(type(suma))
print("exponente = ",exponente)
print("cociente =", cociente)
print("cociente_entero =", cociente_entero)
print("residuo =",residuo)
print("resto",resto)
------------------

----- stdout -----
suma = 45.000001
<class 'float'>
exponente =  25
cociente = 1.8
cociente_entero = 1
residuo = 4
------------------

[31m---------------------------------------------------------------------------[39m
[31mNameError[39m                                 Traceback (most recent call last)
[36mCell[39m[36m [39m[32mIn[3][39m[32m, line 18[39m
[32m     16[39m [38;5;28mprint[39m([33m"[39m[33mcociente_entero =[39m[33m"[39m, cociente_entero)
[32m     17[39m [38;5;28mprint[39m([33m"[39m[33mresiduo =[39m[33m"[39m,residuo)
[32m---> [39m[32m18[39m [38;5;28mprint[39m([33m"[39m[33mresto[39m[33m"[39m,[43mresto[49m)

[31mNameError[39m: name 'resto' is not defined

