Traceback (most recent call last):
  File "/home/victor/anaconda3/envs/jupyterbook/lib/python3.13/site-packages/jupyter_core/utils/__init__.py", line 154, in wrapped
    asyncio.get_running_loop()
    ~~~~~~~~~~~~~~~~~~~~~~~~^^
RuntimeError: no running event loop

During handling of the above exception, another exception occurred:

Traceback (most recent call last):
  File "/home/victor/anaconda3/envs/jupyterbook/lib/python3.13/site-packages/jupyter_cache/executors/utils.py", line 58, in single_nb_execution
    executenb(
    ~~~~~~~~~^
        nb,
        ^^^
    ...<4 lines>...
        **kwargs,
        ^^^^^^^^^
    )
    ^
  File "/home/victor/anaconda3/envs/jupyterbook/lib/python3.13/site-packages/nbclient/client.py", line 1319, in execute
    return NotebookClient(nb=nb, resources=resources, km=km, **kwargs).execute()
           ~~~~~~~~~~~~~~~~~~~~~~~~~~~~~~~~~~~~~~~~~~~~~~~~~~~~~~~~~~~~~~~~~~~^^
  File "/home/victor/anaconda3/envs/jupyterbook/lib/python3.13/site-packages/jupyter_core/utils/__init__.py", line 158, in wrapped
    return loop.run_until_complete(inner)
           ~~~~~~~~~~~~~~~~~~~~~~~^^^^^^^
  File "/home/victor/anaconda3/envs/jupyterbook/lib/python3.13/asyncio/base_events.py", line 725, in run_until_complete
    return future.result()
           ~~~~~~~~~~~~~^^
  File "/home/victor/anaconda3/envs/jupyterbook/lib/python3.13/site-packages/nbclient/client.py", line 709, in async_execute
    await self.async_execute_cell(
        cell, index, execution_count=self.code_cells_executed + 1
    )
  File "/home/victor/anaconda3/envs/jupyterbook/lib/python3.13/site-packages/nbclient/client.py", line 1062, in async_execute_cell
    await self._check_raise_for_error(cell, cell_index, exec_reply)
  File "/home/victor/anaconda3/envs/jupyterbook/lib/python3.13/site-packages/nbclient/client.py", line 918, in _check_raise_for_error
    raise CellExecutionError.from_cell_and_msg(cell, exec_reply_content)
nbclient.exceptions.CellExecutionError: An error occurred while executing the following cell:
------------------
# listas
lista_01 = ["hola", 2024, "mundo", 2024.5]

print(var_lista01)
print(len(var_lista01))
print(var_lista01[0])

var_lista01[3]= "Peru 2025"
print(var_lista01)

print(type(var_lista01[1]))
------------------


[31m---------------------------------------------------------------------------[39m
[31mNameError[39m                                 Traceback (most recent call last)
[36mCell[39m[36m [39m[32mIn[24][39m[32m, line 4[39m
[32m      1[39m [38;5;66;03m# listas[39;00m
[32m      2[39m lista_01 = [[33m"[39m[33mhola[39m[33m"[39m, [32m2024[39m, [33m"[39m[33mmundo[39m[33m"[39m, [32m2024.5[39m]
[32m----> [39m[32m4[39m [38;5;28mprint[39m([43mvar_lista01[49m)
[32m      5[39m [38;5;28mprint[39m([38;5;28mlen[39m(var_lista01))
[32m      6[39m [38;5;28mprint[39m(var_lista01[[32m0[39m])

[31mNameError[39m: name 'var_lista01' is not defined

